
<robot name="TheBoatDoctor">
	<link name="world" />
	<link name="Locomotion">
		<visual>
			<origin rpy="0 0 0" xyz="0. 0 0" />
			<geometry>
				<mesh filename="package://myrobot_description/DAE/Locomotion.dae" scale="1 1 1" />
			</geometry>
		</visual>
		<collision>
			<origin rpy="0 0 1.57" xyz="0. 0 0.08" />
			<geometry>
				<mesh filename="package://myrobot_description/DAE/Locomotion.dae" scale="1 1 1" />
			</geometry>
		</collision>
		<inertial>
			<mass value="1" />
			<origin rpy="0.000000 0.000000 0.000000" xyz="0.000000 0.000000 0.000000" />
			<inertia ixx="1" ixy="0" ixz="0" iyy="1" iyz="0" izz="1" />
		</inertial>
	</link>


	<joint name="joint_world_locomotion" type="fixed">
		<parent link="world" />
		<child link="Locomotion" />
		<origin rpy="0 0 1.57" xyz="0 0 0" />
		<axis xyz="0 0 1" />
	</joint>




	<link name="Turntable">
		<visual>
			<origin rpy="0 0 0" xyz="0. 0 0" />
			<geometry>
				<mesh filename="package://myrobot_description/DAE/Turntable.dae" scale="1 1 1" />
			</geometry>
		</visual>
		<collision>
			<origin rpy="0 0 0" xyz="0. 0 0" />
			<geometry>
				<mesh filename="package://myrobot_description/DAE/Turntable.dae" scale="1 1 1" />
			</geometry>
		</collision>
		<inertial>
			<mass value="1" />
			<origin rpy="0.000000 0.000000 0.000000" xyz="0.000000 0.000000 0.000000" />
			<inertia ixx="1" ixy="0" ixz="0" iyy="1" iyz="0" izz="1" />
		</inertial>
	</link>

	<joint name="turntable" type="revolute">
		<parent link="Locomotion" />
		<child link="Turntable" />
		<origin rpy="0 0 -0.785" xyz="0 0 0.051" />
		<axis xyz="0 0 1" />
		<limit effort="30" velocity="2.0" lower="-3.14" upper="3.14" />
	</joint>




	<link name="XGantry">
		<visual>
			<origin rpy="0 0 0" xyz="0. 0 0" />
			<geometry>
				<mesh filename="package://myrobot_description/DAE/XGantrySkate.dae" scale="1 1 1" />
			</geometry>
		</visual>
		<collision>
			<origin rpy="1.57 0 0" xyz="0. 0 0" />
			<geometry>
				<mesh filename="package://myrobot_description/DAE/XGantrySkate.dae" scale="1 1 1" />
			</geometry>
		</collision>
		<inertial>
			<mass value="1" />
			<origin rpy="0.000000 0.000000 0.000000" xyz="0.000000 0.000000 0.000000" />
			<inertia ixx="1" ixy="0" ixz="0" iyy="1" iyz="0" izz="1" />
		</inertial>
	</link>
	
	<joint name="X_motion" type="prismatic">
		<parent link="Turntable" />
		<child link="XGantry" />
		<origin rpy="0 0 2.3" xyz="0 0 0.055" />
		<axis xyz="0 1 0" />
		<limit effort="30" velocity="2.0" lower="-0.16" upper="0.075" />
		<dynamics damping="0" friction="0" />
	</joint>


	<link name="Kinectv2">
		<visual>
			<origin rpy="0 0 0" xyz="0. 0 0" />
			<geometry>
				<mesh filename="package://myrobot_description/DAE/Kinectv2.dae" scale="1 1 1" />
			</geometry>
		</visual>
		<collision>
			<origin rpy="0 0 0" xyz="0. 0 0" />
			<geometry>
				<mesh filename="package://myrobot_description/DAE/Kinectv2.dae" scale="1 1 1" />
			</geometry>
		</collision>
		<inertial>
			<mass value="1" />
			<origin rpy="0.000000 0.000000 0.000000" xyz="0.000000 0.000000 0.000000" />
			<inertia ixx="1" ixy="0" ixz="0" iyy="1" iyz="0" izz="1" />
		</inertial>
	</link>


	<joint name="joint_Kinectv2" type="fixed">
		<parent link="XGantry" />
		<child link="Kinectv2" />
		<origin rpy="0 0 0" xyz="0 0 0.37" />
		<axis xyz="0 0 1" />
	</joint>


	

	<link name="ZGantry_to_arm">
		<visual>
			<origin rpy="0 0 0" xyz="0. 0 0" />
			<geometry>
				<mesh filename="package://myrobot_description/DAE/ZGantrySkate_TOP.dae" scale="1 1 1" />
			</geometry>
		</visual>
		<collision>
			<origin rpy="0 0 0" xyz="0. 0 0" />
			<geometry>
				<mesh filename="package://myrobot_description/DAE/ZGantrySkate_TOP.dae" scale="1 1 1" />
			</geometry>
		</collision>
		<inertial>
			<mass value="1" />
			<origin rpy="0.000000 0.000000 0.000000" xyz="0.000000 0.000000 0.000000" />
			<inertia ixx="1" ixy="0" ixz="0" iyy="1" iyz="0" izz="1" />
		</inertial>
	</link>

	<joint name="Z_motion" type="prismatic">
		<parent link="XGantry" />
		<child link="ZGantry_to_arm" />
		<origin rpy="0 0 0" xyz="0 0.005 0.05" />
		<axis xyz="0 0 1"/>
		<limit effort="30" velocity="2.0" lower="0" upper="0.38" />
		<dynamics damping="0" friction="0" />
	</joint>

	
	<link name="arm_link">
		<visual>
			<origin rpy="0 0 0" xyz="0. 0 0" />
			<geometry>
				<mesh filename="package://myrobot_description/DAE/ArmLink.dae" scale="1 1 1" />
			</geometry>
		</visual>
		<collision>
			<origin rpy="0 0 0" xyz="0. 0 0" />
			<geometry>
				<mesh filename="package://myrobot_description/DAE/ArmLink.dae" scale="1 1 1" />
			</geometry>
		</collision>
		<inertial>
			<mass value="1" />
			<origin rpy="0.000000 0.000000 0.000000" xyz="0.000000 0.000000 0.000000" />
			<inertia ixx="1" ixy="0" ixz="0" iyy="1" iyz="0" izz="1" />
		</inertial>
	</link>

	<joint name="motor_1" type="revolute">
		<parent link="ZGantry_to_arm" />
		<child link="arm_link" />
		<origin rpy="3.14 0 -1.57" xyz="0.0587 -0.225 -0.01" />
		<axis xyz="0 1 0"/>
		<limit effort="30" velocity="2.0" lower="0" upper="2" />
		<dynamics damping="0" friction="0" />
	</joint>

	
	<link name="end_effctor">
		<visual>
			<origin rpy="0 0 0" xyz="-0.211 0.362 -0.111" />
			<geometry>
				<mesh filename="package://myrobot_description/DAE/EndEffector.dae" scale="1 1 1" />
			</geometry>
		</visual>
		<collision>
			<origin rpy="0 0 0" xyz="0 0 0" />
			<geometry>
				<mesh filename="package://myrobot_description/DAE/EndEffector.dae" scale="1 1 1" />
			</geometry>
		</collision>
		<inertial>
			<mass value="1" />
			<origin rpy="0.000000 0.000000 0.000000" xyz="0.000000 0.000000 0.000000" />
			<inertia ixx="1" ixy="0" ixz="0" iyy="1" iyz="0" izz="1" />
		</inertial>
	</link>

	<joint name="motor_2" type="revolute">
		<parent link="arm_link" />
		<child link="end_effctor" />
		<origin rpy="3.14 0 -1.57" xyz="0.253 0.038 0.0006" />
		<axis xyz="1 0 0"/>
		<limit effort="30" velocity="2.0" lower="-1.57" upper="1.57" />
		<dynamics damping="0" friction="0" />
	</joint>




	
</robot>
